<?xml version='1.0' encoding='utf-8'?>
<robot name="vega-v1-zed">
  <link name="base">
    <inertial>
      <origin xyz="0.01375 0.00093 0.11383" rpy="0 0 0" />
      <mass value="31.81396" />
      <inertia ixx="0.38398" ixy="-0.0005" ixz="-0.03043" iyy="0.39274" iyz="-8.43795E-06"
        izz="0.68293" />
    </inertial>
    <visual>
      <origin xyz="0 0 0" rpy="0 0 0" />
      <geometry>
        <mesh filename="meshes/visual/base.glb" />
      </geometry>
    </visual>
    <collision>
      <origin xyz="0 0 0" rpy="0 0 0" />
      <geometry>
        <mesh filename="meshes/collision/base.obj" />
      </geometry>
    </collision>
  </link>
  <link name="B_wheel_l1">
    <inertial>
      <origin xyz="-0.00642 0.00016 -0.01986" rpy="0 0 0" />
      <mass value="0.08321" />
      <inertia ixx="4.86774E-05" ixy="-1.39149E-07" ixz="-9.44514E-06" iyy="4.56083E-05"
        iyz="4.27003E-07" izz="5.42654E-05" />
    </inertial>
    <visual>
      <origin xyz="0 0 0" rpy="0 0 0" />
      <geometry>
        <mesh filename="meshes/visual/B_wheel_l1.glb" />
      </geometry>
    </visual>
  </link>
  <joint name="B_wheel_j1" type="continuous">
    <origin xyz="-0.265 0 0.044" rpy="0 0 0" />
    <parent link="base" />
    <child link="B_wheel_l1" />
    <axis xyz="0 0 -1" />
  </joint>
  <link name="B_wheel_l2">
    <inertial>
      <origin xyz="-0.00068 -0.01498 6.93889E-18" rpy="0 0 0" />
      <mass value="0.13625" />
      <inertia ixx="6.1102E-05" ixy="1.89907E-06" ixz="1.41126E-22" iyy="0.0001" iyz="3.12122E-21"
        izz="6.10162E-05" />
    </inertial>
    <visual>
      <origin xyz="0 0 0" rpy="0 0 0" />
      <geometry>
        <mesh filename="meshes/visual/B_wheel_l2.glb" />
      </geometry>
    </visual>
    <collision>
      <origin xyz="0 0 0" rpy="0 0 0" />
      <geometry>
        <mesh filename="meshes/collision/B_wheel_l2.obj" />
      </geometry>
    </collision>
  </link>
  <joint name="B_wheel_j2" type="continuous">
    <origin xyz="-0.03329 0.01652 -0.058" rpy="0 0 0" />
    <parent link="B_wheel_l1" />
    <child link="B_wheel_l2" />
    <axis xyz="0.04517 0.99898 0" />
  </joint>
  <link name="R_wheel_l1">
    <inertial>
      <origin xyz="7.45834E-05 0.03713 -0.03504" rpy="0 0 0" />
      <mass value="0.16178" />
      <inertia ixx="0.0003" ixy="6.88081E-08" ixz="-4.89196E-07" iyy="0.00026" iyz="9.85221E-05"
        izz="0.00016" />
    </inertial>
    <visual>
      <origin xyz="0 0 0" rpy="0 0 3.14159" />
      <geometry>
        <mesh filename="meshes/visual/wheel_l1.glb" />
      </geometry>
    </visual>
  </link>
  <joint name="R_wheel_j1" type="revolute">
    <origin xyz="0.185 -0.225 0.133" rpy="0 0 0" />
    <parent link="base" />
    <child link="R_wheel_l1" />
    <axis xyz="0 0 -1" />
    <limit lower="-2.722" upper="2.722" effort="7" velocity="4" />
  </joint>
  <link name="R_wheel_l2">
    <inertial>
      <origin xyz="-7.83171E-18 -0.03937 0" rpy="0 0 0" />
      <mass value="1.21914" />
      <inertia ixx="0.00223" ixy="3.54778E-19" ixz="1.7577E-20" iyy="0.00376" iyz="-8.85953E-20"
        izz="0.00223" />
    </inertial>
    <visual>
      <origin xyz="0 0 0" rpy="0 0 3.14159" />
      <geometry>
        <mesh filename="meshes/visual/wheel_l2.glb" />
      </geometry>
    </visual>
    <collision>
      <origin xyz="0 0 0" rpy="0 0 3.14159" />
      <geometry>
        <mesh filename="meshes/collision/wheel_l2.obj" />
      </geometry>
    </collision>
  </link>
  <joint name="R_wheel_j2" type="continuous">
    <origin xyz="0 0.0395 -0.1005" rpy="0 0 0" />
    <parent link="R_wheel_l1" />
    <child link="R_wheel_l2" />
    <axis xyz="0 -1 0" />
    <limit effort="18" velocity="15" />
  </joint>
  <link name="L_wheel_l1">
    <inertial>
      <origin xyz="-7.45834E-05 -0.03713 -0.03504" rpy="0 0 0" />
      <mass value="0.16178" />
      <inertia ixx="0.0003" ixy="6.88081E-08" ixz="4.89196E-07" iyy="0.00026" iyz="-9.85221E-05"
        izz="0.00016" />
    </inertial>
    <visual>
      <origin xyz="0 0 0" rpy="0 0 0" />
      <geometry>
        <mesh filename="meshes/visual/wheel_l1.glb" />
      </geometry>
    </visual>
  </link>
  <joint name="L_wheel_j1" type="revolute">
    <origin xyz="0.185 0.225 0.133" rpy="0 0 0" />
    <parent link="base" />
    <child link="L_wheel_l1" />
    <axis xyz="0 0 -1" />
    <limit lower="-2.722" upper="2.722" effort="7" velocity="4" />
  </joint>
  <link name="L_wheel_l2">
    <inertial>
      <origin xyz="-1.64965E-17 0.03937 0" rpy="0 0 0" />
      <mass value="1.21914" />
      <inertia ixx="0.00223" ixy="-6.15518E-19" ixz="-1.76803E-20" iyy="0.00376" iyz="-1.66647E-19"
        izz="0.00223" />
    </inertial>
    <visual>
      <origin xyz="0 0 0" rpy="0 0 0" />
      <geometry>
        <mesh filename="meshes/visual/wheel_l2.glb" />
      </geometry>
    </visual>
    <collision>
      <origin xyz="0 0 0" rpy="0 0 0" />
      <geometry>
        <mesh filename="meshes/collision/wheel_l2.obj" />
      </geometry>
    </collision>
  </link>
  <joint name="L_wheel_j2" type="continuous">
    <origin xyz="0 -0.0395 -0.1005" rpy="0 0 0" />
    <parent link="L_wheel_l1" />
    <child link="L_wheel_l2" />
    <axis xyz="0 1 0" />
    <limit effort="18" velocity="15" />
  </joint>
  <link name="torso_l1">
    <inertial>
      <origin xyz="0.17712 -0.06463 0.03987" rpy="0 0 0" />
      <mass value="2.84914" />
      <inertia ixx="0.01062" ixy="-0.00022" ixz="-0.01093" iyy="0.07152" iyz="-0.00018" izz="0.067" />
    </inertial>
    <visual>
      <origin xyz="0 0 0" rpy="0 0 0" />
      <geometry>
        <mesh filename="meshes/visual/torso_l1.glb" />
      </geometry>
    </visual>
    <collision>
      <origin xyz="0 0 0" rpy="0 0 0" />
      <geometry>
        <mesh filename="meshes/collision/torso_l1.obj" />
      </geometry>
    </collision>
  </link>
  <joint name="torso_j1" type="revolute">
    <origin xyz="-0.235 0.08 0.248" rpy="0 0 0" />
    <parent link="base" />
    <child link="torso_l1" />
    <axis xyz="0 -1 0" />
    <limit lower="0" upper="1.570" effort="802" velocity="1.47" />
  </joint>
  <link name="torso_l2">
    <inertial>
      <origin xyz="-0.19819 -0.02173 0.04732" rpy="0 0 0" />
      <mass value="2.07381" />
      <inertia ixx="0.00776" ixy="-0.00013" ixz="0.01024" iyy="0.05911" iyz="3.13396E-05"
        izz="0.05463" />
    </inertial>
    <visual>
      <origin xyz="0 0 0" rpy="0 0 0" />
      <geometry>
        <mesh filename="meshes/visual/torso_l2.glb" />
      </geometry>
    </visual>
    <collision>
      <origin xyz="0 0 0" rpy="0 0 0" />
      <geometry>
        <mesh filename="meshes/collision/torso_l2.obj" />
      </geometry>
    </collision>
  </link>
  <joint name="torso_j2" type="revolute">
    <origin xyz="0.396 -0.06 0.082" rpy="0 0 0" />
    <parent link="torso_l1" />
    <child link="torso_l2" />
    <axis xyz="0 1 0" />
    <limit lower="0" upper="3.141" effort="436" velocity="2.51" />
  </joint>
  <link name="torso_l3">
    <inertial>
      <origin xyz="-0.05623 -0.08424 0.25675" rpy="0 0 0" />
      <mass value="2.30133" />
      <inertia ixx="0.04617" ixy="-0.00102" ixz="0.00625" iyy="0.04404" iyz="0.00474" izz="0.01142" />
    </inertial>
    <visual>
      <origin xyz="0 0 0" rpy="0 0 0" />
      <geometry>
        <mesh filename="meshes/visual/torso_l3.glb" />
      </geometry>
    </visual>
    <collision>
      <origin xyz="0 0 0" rpy="0 0 0" />
      <geometry>
        <mesh filename="meshes/collision/torso_l3.obj" />
      </geometry>
    </collision>
  </link>
  <joint name="torso_j3" type="revolute">
    <origin xyz="-0.40718 0.058 0.09764" rpy="0 0 0" />
    <parent link="torso_l2" />
    <child link="torso_l3" />
    <axis xyz="0 -1 0" />
    <limit lower="-1.570" upper="1.570" effort="436" velocity="2.51" />
  </joint>
  <link name="head_l1">
    <inertial>
      <origin xyz="1.30097E-05 0.07221 -0.02629" rpy="0 0 0" />
      <mass value="0.2189" />
      <inertia ixx="0.00022" ixy="7.12442E-09" ixz="3.58817E-08" iyy="0.00012" iyz="-5.05425E-07"
        izz="0.00026" />
    </inertial>
    <visual>
      <origin xyz="0 0 0" rpy="0 0 0" />
      <geometry>
        <mesh filename="meshes/visual/head_l1.glb" />
      </geometry>
    </visual>
    <collision>
      <origin xyz="0 0 0" rpy="0 0 0" />
      <geometry>
        <mesh filename="meshes/collision/head_l1.obj" />
      </geometry>
    </collision>
  </link>
  <joint name="head_j1" type="revolute">
    <origin xyz="-0.13258 -0.1505 0.45928" rpy="0 0 0" />
    <parent link="torso_l3" />
    <child link="head_l1" />
    <axis xyz="0 1 0" />
    <limit lower="-1.483" upper="1.483" effort="7" velocity="3.14" />
  </joint>
  <link name="head_l2">
    <inertial>
      <origin xyz="3.533E-05 0.01618 0.03389" rpy="0 0 0" />
      <mass value="0.21704" />
      <inertia ixx="0.00019" ixy="2.8808E-08" ixz="-7.0744E-09" iyy="0.00014" iyz="-3.60005E-05"
        izz="0.00018" />
    </inertial>
    <visual>
      <origin xyz="0 0 0" rpy="0 0 0" />
      <geometry>
        <mesh filename="meshes/visual/head_l2.glb" />
      </geometry>
    </visual>
    <collision>
      <origin xyz="0 0 0" rpy="0 0 0" />
      <geometry>
        <mesh filename="meshes/collision/head_l2.obj" />
      </geometry>
    </collision>
  </link>
  <joint name="head_j2" type="revolute">
    <origin xyz="0 0.0725 -0.0035" rpy="0 0 0" />
    <parent link="head_l1" />
    <child link="head_l2" />
    <axis xyz="0 0 1" />
    <limit lower="-2.792" upper="2.792" effort="2.7" velocity="3.14" />
  </joint>
  <link name="head_l3">
    <inertial>
      <origin xyz="0.00816 -0.00315 0.03745" rpy="0 0 0" />
      <mass value="0.22599" />
      <inertia ixx="0.00029" ixy="-7.97223E-07" ixz="-3.47802E-06" iyy="0.00012" iyz="-3.24875E-06"
        izz="0.00028" />
    </inertial>
    <visual>
      <origin xyz="0 0 0" rpy="0 0 0" />
      <geometry>
        <mesh filename="meshes/visual/head_l3.glb" />
      </geometry>
    </visual>
    <collision>
      <origin xyz="0 0 0" rpy="0 0 0" />
      <geometry>
        <mesh filename="meshes/collision/head_l3.obj" />
      </geometry>
    </collision>
  </link>
  <joint name="head_j3" type="revolute">
    <origin xyz="0 0.002 0.0495" rpy="0 0 0" />
    <parent link="head_l2" />
    <child link="head_l3" />
    <axis xyz="0 -1 0" />
    <limit lower="-1.378" upper="1.483" effort="7" velocity="3.14" />
  </joint>
  <link name="L_arm_l1">
    <inertial>
      <origin xyz="0.0285 0.05287 0.00576" rpy="0 0 0" />
      <mass value="0.24689" />
      <inertia ixx="0.00019" ixy="-1.14453E-05" ixz="4.73162E-07" iyy="0.00022" iyz="-1.887E-07"
        izz="0.00033" />
    </inertial>
    <visual>
      <origin xyz="0 0 0" rpy="0 0 0" />
      <geometry>
        <mesh filename="meshes/visual/L_arm_l1.glb" />
      </geometry>
    </visual>
    <collision>
      <origin xyz="0 0 0" rpy="0 0 0" />
      <geometry>
        <mesh filename="meshes/collision/L_arm_l1.obj" />
      </geometry>
    </collision>
  </link>
  <joint name="L_arm_j1" type="revolute">
    <origin xyz="-0.05908 0.09146 0.44528" rpy="0 0 0" />
    <parent link="torso_l3" />
    <child link="L_arm_l1" />
    <axis xyz="0 1 0" />
    <limit lower="-3.071" upper="3.071" effort="180" velocity="3.14" />
  </joint>
  <link name="L_arm_l2">
    <inertial>
      <origin xyz="0.08194 -1.45468E-06 -0.04058" rpy="0 0 0" />
      <mass value="0.17057" />
      <inertia ixx="0.00016" ixy="1.21422E-10" ixz="2.8552E-06" iyy="0.00035" iyz="5.44743E-10"
        izz="0.0004" />
    </inertial>
    <visual>
      <origin xyz="0 0 0" rpy="0 0 0" />
      <geometry>
        <mesh filename="meshes/visual/arm_l2.glb" />
      </geometry>
    </visual>
    <collision>
      <origin xyz="0 0 0" rpy="0 0 0" />
      <geometry>
        <mesh filename="meshes/collision/arm_l2.obj" />
      </geometry>
    </collision>
  </link>
  <joint name="L_arm_j2" type="revolute">
    <origin xyz="0.04 0.06 0.0454" rpy="0 0 0" />
    <parent link="L_arm_l1" />
    <child link="L_arm_l2" />
    <axis xyz="0 0 1" />
    <limit lower="-0.453" upper="1.553" effort="180" velocity="3.14" />
  </joint>
  <link name="L_arm_l3">
    <inertial>
      <origin xyz="0.07978 0.00403 0.0398" rpy="0 0 0" />
      <mass value="0.2299" />
      <inertia ixx="0.00019" ixy="1.3436E-06" ixz="-6.62122E-05" iyy="0.00038" iyz="1.39597E-06"
        izz="0.00025" />
    </inertial>
    <visual>
      <origin xyz="0 0 0" rpy="0 0 0" />
      <geometry>
        <mesh filename="meshes/visual/arm_l3.glb" />
      </geometry>
    </visual>
    <collision>
      <origin xyz="0 0 0" rpy="0 0 0" />
      <geometry>
        <mesh filename="meshes/collision/arm_l3.obj" />
      </geometry>
    </collision>
  </link>
  <joint name="L_arm_j3" type="revolute">
    <origin xyz="0.1644 0 -0.043" rpy="0 0 0" />
    <parent link="L_arm_l2" />
    <child link="L_arm_l3" />
    <axis xyz="1 0 0" />
    <limit lower="-3.071" upper="3.071" effort="90" velocity="3.93" />
  </joint>
  <link name="L_arm_l4">
    <inertial>
      <origin xyz="0.09219 -0.03791 -0.02953" rpy="0 0 0" />
      <mass value="0.28335" />
      <inertia ixx="0.00025" ixy="1.2867E-05" ixz="0.00011" iyy="0.00065" iyz="-1.60044E-05"
        izz="0.00055" />
    </inertial>
    <visual>
      <origin xyz="0 0 0" rpy="0 0 0" />
      <geometry>
        <mesh filename="meshes/visual/arm_l4.glb" />
      </geometry>
    </visual>
    <collision>
      <origin xyz="0 0 0" rpy="0 0 0" />
      <geometry>
        <mesh filename="meshes/collision/arm_l4.obj" />
      </geometry>
    </collision>
  </link>
  <joint name="L_arm_j4" type="revolute">
    <origin xyz="0.113 0.0433 0.06" rpy="0 0 0" />
    <parent link="L_arm_l3" />
    <child link="L_arm_l4" />
    <axis xyz="0 1 0" />
    <limit lower="-3.071" upper="0.244" effort="90" velocity="3.93" />
  </joint>
  <link name="L_arm_l5">
    <inertial>
      <origin xyz="0.06497 -0.00266 1.20027E-05" rpy="0 0 0" />
      <mass value="0.21021" />
      <inertia ixx="0.00011" ixy="3.08906E-06" ixz="-5.18729E-08" iyy="0.00014" iyz="1.5559E-08"
        izz="0.00014" />
    </inertial>
    <visual>
      <origin xyz="0 0 0" rpy="0 0 0" />
      <geometry>
        <mesh filename="meshes/visual/arm_l5.glb" />
      </geometry>
    </visual>
    <collision>
      <origin xyz="0 0 0" rpy="0 0 0" />
      <geometry>
        <mesh filename="meshes/collision/arm_l5.obj" />
      </geometry>
    </collision>
  </link>
  <joint name="L_arm_j5" type="revolute">
    <origin xyz="0.1938 -0.0434 -0.04" rpy="0 0 0" />
    <parent link="L_arm_l4" />
    <child link="L_arm_l5" />
    <axis xyz="1 0 0" />
    <limit lower="-3.071" upper="3.071" effort="30" velocity="3.93" />
  </joint>
  <link name="L_arm_l6">
    <inertial>
      <origin xyz="0.05526 -0.02615 -0.00267" rpy="0 0 0" />
      <mass value="0.20526" />
      <inertia ixx="0.00011" ixy="1.81134E-05" ixz="6.68986E-07" iyy="0.00015" iyz="-5.22269E-07"
        izz="0.00014" />
    </inertial>
    <visual>
      <origin xyz="0 0 0" rpy="0 0 0" />
      <geometry>
        <mesh filename="meshes/visual/L_arm_l6.glb" />
      </geometry>
    </visual>
    <collision>
      <origin xyz="0 0 0" rpy="0 0 0" />
      <geometry>
        <mesh filename="meshes/collision/L_arm_l6.obj" />
      </geometry>
    </collision>
  </link>
  <joint name="L_arm_j6" type="revolute">
    <origin xyz="0.0762 0.0319 0" rpy="0 0 0" />
    <parent link="L_arm_l5" />
    <child link="L_arm_l6" />
    <axis xyz="0 1 0" />
    <limit lower="-1.396" upper="1.396" effort="30" velocity="3.93" />
  </joint>
  <link name="L_arm_l7">
    <inertial>
      <origin xyz="0.032 5.48376E-05 -0.01786" rpy="0 0 0" />
      <mass value="0.06296" />
      <inertia ixx="3.85975E-05" ixy="-6.27756E-09" ixz="6.5825E-06" iyy="4.0247E-05"
        iyz="-7.37881E-09" izz="5.84186E-05" />
    </inertial>
    <visual>
      <origin xyz="0 0 0" rpy="0 0 0" />
      <geometry>
        <mesh filename="meshes/visual/arm_l7.glb" />
      </geometry>
    </visual>
    <collision>
      <origin xyz="0 0 0" rpy="0 0 0" />
      <geometry>
        <mesh filename="meshes/collision/arm_l7.obj" />
      </geometry>
    </collision>
  </link>
  <joint name="L_arm_j7" type="revolute">
    <origin xyz="0.065 -0.032 0.0319" rpy="0 0 0" />
    <parent link="L_arm_l6" />
    <child link="L_arm_l7" />
    <axis xyz="0 0 1" />
    <limit lower="-1.378" upper="1.117" effort="30" velocity="3.93" />
  </joint>
  <link name="L_arm_l8">
    <inertial>
      <origin xyz="-0.01782 -0.00021 0.00027" rpy="0 0 0" />
      <mass value="0.07431" />
      <inertia ixx="3.42446E-05" ixy="2.93402E-08" ixz="1.26617E-07" iyy="2.12153E-05"
        iyz="8.02183E-08" izz="2.10214E-05" />
    </inertial>
    <visual>
      <origin xyz="0 0 0" rpy="0 0 0" />
      <geometry>
        <mesh filename="meshes/visual/arm_l8.glb" />
      </geometry>
    </visual>
    <collision>
      <origin xyz="0 0 0" rpy="0 0 0" />
      <geometry>
        <mesh filename="meshes/collision/arm_l8.obj" />
      </geometry>
    </collision>
  </link>
  <joint name="L_arm_j8" type="fixed">
    <origin xyz="0.11597 0 -0.032" rpy="0 0 0" />
    <parent link="L_arm_l7" />
    <child link="L_arm_l8" />
    <axis xyz="0 0 0" />
  </joint>
  <link name="L_ee" />
  <joint name="L_ee_j0" type="fixed">
    <origin xyz="0 0 0" rpy="-1.57079 0 -1.57079" />
    <parent link="L_arm_l8" />
    <child link="L_ee" />
  </joint>

  <link name="R_arm_l1">
    <inertial>
      <origin xyz="0.02833 -0.05 0.0054" rpy="0 0 0" />
      <mass value="0.26325" />
      <inertia ixx="0.00027" ixy="4.79246E-05" ixz="4.58885E-07" iyy="0.00024" iyz="-1.88653E-07"
        izz="0.00043" />
    </inertial>
    <visual>
      <origin xyz="0 0 0" rpy="0 0 0" />
      <geometry>
        <mesh filename="meshes/visual/R_arm_l1.glb" />
      </geometry>
    </visual>
    <collision>
      <origin xyz="0 0 0" rpy="0 0 0" />
      <geometry>
        <mesh filename="meshes/collision/R_arm_l1.obj" />
      </geometry>
    </collision>
  </link>
  <joint name="R_arm_j1" type="revolute">
    <origin xyz="-0.05908 -0.24746 0.44528" rpy="0 0 0" />
    <parent link="torso_l3" />
    <child link="R_arm_l1" />
    <axis xyz="0 -1 0" />
    <limit lower="-3.071" upper="3.071" effort="180" velocity="3.14" />
  </joint>
  <link name="R_arm_l2">
    <inertial>
      <origin xyz="0.08749 -1.34526E-06 -0.04135" rpy="0 0 0" />
      <mass value="0.18345" />
      <inertia ixx="0.00017" ixy="1.41671E-10" ixz="2.88819E-06" iyy="0.00036" iyz="5.62291E-11"
        izz="0.00041" />
    </inertial>
    <visual>
      <origin xyz="0 0 0" rpy="0 0 0" />
      <geometry>
        <mesh filename="meshes/visual/arm_l2.glb" />
      </geometry>
    </visual>
    <collision>
      <origin xyz="0 0 0" rpy="0 0 0" />
      <geometry>
        <mesh filename="meshes/collision/arm_l2.obj" />
      </geometry>
    </collision>
  </link>
  <joint name="R_arm_j2" type="revolute">
    <origin xyz="0.04 -0.06 0.0454" rpy="0 0 0" />
    <parent link="R_arm_l1" />
    <child link="R_arm_l2" />
    <axis xyz="0 0 1" />
    <limit lower="-1.553" upper="0.453" effort="180" velocity="3.14" />
  </joint>
  <link name="R_arm_l3">
    <inertial>
      <origin xyz="0.08127 0.00414 0.04053" rpy="0 0 0" />
      <mass value="0.22384" />
      <inertia ixx="0.00019" ixy="1.41946E-06" ixz="-6.59147E-05" iyy="0.00038" iyz="8.3059E-07"
        izz="0.00025" />
    </inertial>
    <visual>
      <origin xyz="0 0 0" rpy="0 0 0" />
      <geometry>
        <mesh filename="meshes/visual/arm_l3.glb" />
      </geometry>
    </visual>
    <collision>
      <origin xyz="0 0 0" rpy="0 0 0" />
      <geometry>
        <mesh filename="meshes/collision/arm_l3.obj" />
      </geometry>
    </collision>
  </link>
  <joint name="R_arm_j3" type="revolute">
    <origin xyz="0.1644 0 -0.043" rpy="0 0 0" />
    <parent link="R_arm_l2" />
    <child link="R_arm_l3" />
    <axis xyz="1 0 0" />
    <limit lower="-3.14" upper="3.14" effort="90" velocity="3.93" />
  </joint>
  <link name="R_arm_l4">
    <inertial>
      <origin xyz="0.07728 -0.03736 -0.02906" rpy="0 0 0" />
      <mass value="0.25609" />
      <inertia ixx="0.00027" ixy="1.83596E-05" ixz="0.00011" iyy="0.00065" iyz="-2.72687E-05"
        izz="0.00055" />
    </inertial>
    <visual>
      <origin xyz="0 0 0" rpy="0 0 0" />
      <geometry>
        <mesh filename="meshes/visual/arm_l4.glb" />
      </geometry>
    </visual>
    <collision>
      <origin xyz="0 0 0" rpy="0 0 0" />
      <geometry>
        <mesh filename="meshes/collision/arm_l4.obj" />
      </geometry>
    </collision>
  </link>
  <joint name="R_arm_j4" type="revolute">
    <origin xyz="0.113 0.0433 0.06" rpy="0 0 0" />
    <parent link="R_arm_l3" />
    <child link="R_arm_l4" />
    <axis xyz="0 1 0" />
    <limit lower="-3.14" upper="0.313" effort="90" velocity="3.93" />
  </joint>
  <link name="R_arm_l5">
    <inertial>
      <origin xyz="0.06457 0.0025 -1.30383E-05" rpy="0 0 0" />
      <mass value="0.21223" />
      <inertia ixx="0.00011" ixy="-2.93839E-06" ixz="5.82462E-08" iyy="0.00014" iyz="9.77062E-09"
        izz="0.00014" />
    </inertial>
    <visual>
      <origin xyz="0 0 0" rpy="3.14159 0 0" />
      <geometry>
        <mesh filename="meshes/visual/arm_l5.glb" />
      </geometry>
    </visual>
    <collision>
      <origin xyz="0 0 0" rpy="3.14159 0 0" />
      <geometry>
        <mesh filename="meshes/collision/arm_l5.obj" />
      </geometry>
    </collision>
  </link>
  <joint name="R_arm_j5" type="revolute">
    <origin xyz="0.1938 -0.0434 -0.04" rpy="0 0 0" />
    <parent link="R_arm_l4" />
    <child link="R_arm_l5" />
    <axis xyz="1 0 0" />
    <limit lower="-3.14" upper="3.14" effort="30" velocity="3.93" />
  </joint>
  <link name="R_arm_l6">
    <inertial>
      <origin xyz="0.05525 0.02614 -0.00267" rpy="0 0 0" />
      <mass value="0.20508" />
      <inertia ixx="0.00011" ixy="-1.81743E-05" ixz="6.89091E-07" iyy="0.00015" iyz="5.4206E-07"
        izz="0.00014" />
    </inertial>
    <visual>
      <origin xyz="0 0 0" rpy="0 0 0" />
      <geometry>
        <mesh filename="meshes/visual/R_arm_l6.glb" />
      </geometry>
    </visual>
    <collision>
      <origin xyz="0 0 0" rpy="0 0 0" />
      <geometry>
        <mesh filename="meshes/collision/R_arm_l6.obj" />
      </geometry>
    </collision>
  </link>
  <joint name="R_arm_j6" type="revolute">
    <origin xyz="0.0762 -0.0319 0" rpy="0 0 0" />
    <parent link="R_arm_l5" />
    <child link="R_arm_l6" />
    <axis xyz="0 -1 0" />
    <limit lower="-1.462" upper="1.462" effort="30" velocity="3.93" />
  </joint>
  <link name="R_arm_l7">
    <inertial>
      <origin xyz="0.03048 5.11736E-05 -0.01709" rpy="0 0 0" />
      <mass value="0.06731" />
      <inertia ixx="4.14578E-05" ixy="-7.39808E-09" ixz="9.04316E-06" iyy="4.67546E-05"
        iyz="-6.88155E-09" izz="6.51177E-05" />
    </inertial>
    <visual>
      <origin xyz="0 0 0" rpy="0 0 0" />
      <geometry>
        <mesh filename="meshes/visual/arm_l7.glb" />
      </geometry>
    </visual>
    <collision>
      <origin xyz="0 0 0" rpy="0 0 0" />
      <geometry>
        <mesh filename="meshes/collision/arm_l7.obj" />
      </geometry>
    </collision>
  </link>
  <joint name="R_arm_j7" type="revolute">
    <origin xyz="0.065 0.032 0.0319" rpy="0 0 0" />
    <parent link="R_arm_l6" />
    <child link="R_arm_l7" />
    <axis xyz="0 0 1" />
    <limit lower="-1.183" upper="1.444" effort="30" velocity="3.93" />
  </joint>
  <link name="R_arm_l8">
    <inertial>
      <origin xyz="-0.01782 1.03176E-06 0.00027" rpy="0 0 0" />
      <mass value="0.07431" />
      <inertia ixx="3.42446E-05" ixy="-3.10006E-08" ixz="1.26617E-07" iyy="2.12153E-05"
        iyz="8.02183E-08" izz="2.10214E-05" />
    </inertial>
    <visual>
      <origin xyz="0 0 0" rpy="0 0 0" />
      <geometry>
        <mesh filename="meshes/visual/arm_l8.glb" />
      </geometry>
    </visual>
    <collision>
      <origin xyz="0 0 0" rpy="0 0 0" />
      <geometry>
        <mesh filename="meshes/collision/arm_l8.obj" />
      </geometry>
    </collision>
  </link>
  <joint name="R_arm_j8" type="fixed">
    <origin xyz="0.11597 0 -0.032" rpy="0 0 0" />
    <parent link="R_arm_l7" />
    <child link="R_arm_l8" />
    <axis xyz="0 0 0" />
  </joint>
  <link name="R_ee" />
  <joint name="R_ee_j0" type="fixed">
    <origin xyz="0 0 0" rpy="1.57079 0 1.57079" />
    <parent link="R_arm_l8" />
    <child link="R_ee" />
  </joint>

  <link name="lidar">
    <inertial>
      <origin xyz="-0.00548 3.47734E-05 -0.00608" rpy="0 0 0" />
      <mass value="0.00423" />
      <inertia ixx="1.38704E-07" ixy="1.77495E-14" ixz="-1.01452E-10" iyy="1.36178E-07"
        iyz="-2.22399E-15" izz="1.6409E-07" />
    </inertial>
    <visual>
      <origin xyz="0 0 0" rpy="0 0 0" />
      <geometry>
        <mesh filename="meshes/visual/lidar.glb" />
      </geometry>
    </visual>
  </link>
  <joint name="lidar_mount" type="fixed">
    <origin xyz="0.2975 0 0.144" rpy="0 0 0" />
    <parent link="base" />
    <child link="lidar" />
    <axis xyz="0 0 0" />
  </joint>
  <link name="imu">
    <inertial>
      <origin xyz="6.06827E-05 -5.84386E-18 -0.00788" rpy="0 0 0" />
      <mass value="0.01779" />
      <inertia ixx="2.22862E-06" ixy="-2.07088E-22" ixz="3.66731E-09" iyy="1.97585E-06"
        iyz="-1.34274E-22" izz="3.49443E-06" />
    </inertial>
    <visual>
      <origin xyz="0 0 0" rpy="0 0 0" />
      <geometry>
        <mesh filename="meshes/visual/imu.glb" />
      </geometry>
    </visual>
  </link>
  <joint name="imu_mount" type="fixed">
    <origin xyz="0.165 0 0.2071" rpy="0 0 0" />
    <parent link="base" />
    <child link="imu" />
    <axis xyz="0 0 0" />
  </joint>
  <link name="L_base_cam">
    <inertial>
      <origin xyz="-0.00857 -2.77556E-17 -0.001" rpy="0 0 0" />
      <mass value="0.00309" />
      <inertia ixx="1.66577E-07" ixy="-1.91034E-23" ixz="1.13265E-23" iyy="9.21398E-08"
        iyz="8.88173E-24" izz="1.22898E-07" />
    </inertial>
    <visual>
      <origin xyz="0 0 0" rpy="0 0 0" />
      <geometry>
        <mesh filename="meshes/visual/base_cam.glb" />
      </geometry>
    </visual>
  </link>
  <joint name="L_base_cam_mount" type="fixed">
    <origin xyz="0.02 0.2673 0.208" rpy="0 0 1.5708" />
    <parent link="base" />
    <child link="L_base_cam" />
    <axis xyz="0 0 0" />
  </joint>
  <link name="R_base_cam">
    <inertial>
      <origin xyz="-0.00857 2.77556E-17 -0.001" rpy="0 0 0" />
      <mass value="0.00309" />
      <inertia ixx="1.66577E-07" ixy="7.23081E-24" ixz="9.22687E-25" iyy="9.21398E-08"
        iyz="-1.69205E-22" izz="1.22898E-07" />
    </inertial>
    <visual>
      <origin xyz="0 0 0" rpy="0 0 0" />
      <geometry>
        <mesh filename="meshes/visual/base_cam.glb" />
      </geometry>
    </visual>
  </link>
  <joint name="R_base_cam_mount" type="fixed">
    <origin xyz="0.02 -0.2673 0.208" rpy="0 0 -1.5708" />
    <parent link="base" />
    <child link="R_base_cam" />
    <axis xyz="0 0 0" />
  </joint>
  <link name="F_base_cam">
    <inertial>
      <origin xyz="-0.00857 1.01381E-17 -0.001" rpy="0 0 0" />
      <mass value="0.00309" />
      <inertia ixx="1.66577E-07" ixy="-1.64559E-23" ixz="-6.41597E-24" iyy="9.21398E-08"
        iyz="1.29109E-22" izz="1.22898E-07" />
    </inertial>
    <visual>
      <origin xyz="0 0 0" rpy="0 0 0" />
      <geometry>
        <mesh filename="meshes/visual/base_cam.glb" />
      </geometry>
    </visual>
  </link>
  <joint name="F_base_cam_mount" type="fixed">
    <origin xyz="0.3373 0 0.208" rpy="0 0 0" />
    <parent link="base" />
    <child link="F_base_cam" />
    <axis xyz="0 0 0" />
  </joint>
  <link name="B_base_cam">
    <inertial>
      <origin xyz="-0.00857 -1.99967E-19 -0.001" rpy="0 0 0" />
      <mass value="0.00309" />
      <inertia ixx="1.66577E-07" ixy="5.77269E-24" ixz="3.0439E-23" iyy="9.21398E-08"
        iyz="-2.66772E-23" izz="1.22898E-07" />
    </inertial>
    <visual>
      <origin xyz="0 0 0" rpy="0 0 0" />
      <geometry>
        <mesh filename="meshes/visual/base_cam.glb" />
      </geometry>
    </visual>
  </link>
  <joint name="B_base_cam_mount" type="fixed">
    <origin xyz="-0.3303 0 0.176" rpy="0 0 3.1416" />
    <parent link="base" />
    <child link="B_base_cam" />
    <axis xyz="0 0 0" />
  </joint>
  <link name="LF_ultrasonic">
    <inertial>
      <origin xyz="-0.00984 -0.00459 -0.00495" rpy="0 0 0" />
      <mass value="0.01186" />
      <inertia ixx="1.13153E-06" ixy="1.72173E-07" ixz="-8.76866E-08" iyy="8.4259E-07"
        iyz="-4.08889E-08" izz="1.31676E-06" />
    </inertial>
    <visual>
      <origin xyz="0 0 0" rpy="0 0 0" />
      <geometry>
        <mesh filename="meshes/visual/ultrasonic.glb" />
      </geometry>
    </visual>
  </link>
  <joint name="LF_ultrasonic_mount" type="fixed">
    <origin xyz="0.31642 0.14755 0.15853" rpy="0.01745 -0.41887 0.43633" />
    <parent link="base" />
    <child link="LF_ultrasonic" />
  </joint>
  <link name="RF_ultrasonic">
    <inertial>
      <origin xyz="-0.00984 0.00459 -0.00495" rpy="0 0 0" />
      <mass value="0.01186" />
      <inertia ixx="1.13153E-06" ixy="-1.72173E-07" ixz="-8.76866E-08" iyy="8.4259E-07"
        iyz="4.08889E-08" izz="1.31676E-06" />
    </inertial>
    <visual>
      <origin xyz="0 0 0" rpy="0 0 0" />
      <geometry>
        <mesh filename="meshes/visual/ultrasonic.glb" />
      </geometry>
    </visual>
  </link>
  <joint name="RF_ultrasonic_mount" type="fixed">
    <origin xyz="0.31642 -0.14755 0.15853" rpy="0.01745 -0.41887 -0.43633" />
    <parent link="base" />
    <child link="RF_ultrasonic" />
    <axis xyz="0 0 0" />
  </joint>
  <link name="LB_ultrasonic">
    <inertial>
      <origin xyz="-0.01193 0 -0.00011" rpy="0 0 0" />
      <mass value="0.01186" />
      <inertia ixx="1.15728E-06" ixy="5.15596E-09" ixz="0" iyy="7.86731E-07" iyz="-1.19495E-07"
        izz="1.34687E-06" />
    </inertial>
    <visual>
      <origin xyz="0 0 0" rpy="0 0 0" />
      <geometry>
        <mesh filename="meshes/visual/ultrasonic.glb" />
      </geometry>
    </visual>
  </link>
  <joint name="LB_ultrasonic_mount" type="fixed">
    <origin xyz="-0.31633 0.14751 0.07886" rpy="0 -0.45379 2.7053" />
    <parent link="base" />
    <child link="LB_ultrasonic" />
    <axis xyz="0 0 0" />
  </joint>
  <link name="RB_ultrasonic">
    <inertial>
      <origin xyz="-0.01193 0 -0.00011" rpy="0 0 0" />
      <mass value="0.01186" />
      <inertia ixx="1.15728E-06" ixy="5.15596E-09" ixz="0" iyy="7.86731E-07" iyz="-1.19495E-07"
        izz="1.34687E-06" />
    </inertial>
    <visual>
      <origin xyz="0 0 0" rpy="0 0 0" />
      <geometry>
        <mesh filename="meshes/visual/ultrasonic.glb" />
      </geometry>
    </visual>
  </link>
  <joint name="RB_ultrasonic_mount" type="fixed">
    <origin xyz="-0.31633 -0.14751 0.07886" rpy="0 -0.45379 -2.70526" />
    <parent link="base" />
    <child link="RB_ultrasonic" />
    <axis xyz="0 0 0" />
  </joint>

  <!-- Left Hand With Tesollo 3F Gripper -->
  <material name="silver">
    <color rgba="0.700 0.700 0.700 1.000" />
  </material>
  <material name="black">
    <color rgba="0.196 0.196 0.196 1.0" />
  </material>
  <material name="white">
    <color rgba="1.0 1.0 1.0 1.0" />
  </material>

  <joint name="L_hand_mount" type="fixed">
    <origin xyz="0.10727 0 0" rpy="1.5708 0 1.5708" />
    <parent link="L_arm_l8" />
    <child link="L_hand_base" />
  </joint>
  <link name="L_hand_base">
    <visual>
      <origin xyz="0 0 -0.11077" rpy="0 -1.5708 0" />
      <geometry>
        <mesh filename="../../../hands/tesollo_3f/meshes/visual/adapter.stl" />
      </geometry>
      <material name="black" />
    </visual>
    <inertial>
      <origin xyz="0.00045 -2.05165e-06 -0.05219" rpy="5.67132e-06 0.00329 -0.00045" />
      <mass value="0.370" />
      <inertia ixx="0.00099" iyy="0.00098" izz="0.00032" ixy="0" ixz="0" iyz="0" />
    </inertial>
    <visual>
      <origin xyz="0.00045 -2.05165e-06 -0.05219" rpy="5.67132e-06 0.00329 -0.00045" />
      <geometry>
        <mesh filename="../../../hands/tesollo_3f/meshes/visual/delto_base_link.stl" />
      </geometry>
      <material name="black" />
    </visual>
    <collision>
      <origin xyz="0.00045 -2.05165e-06 -0.05219" rpy="5.67132e-06 0.00329 -0.00045" />
      <geometry>
        <mesh filename="../../../hands/tesollo_3f/meshes/visual/delto_base_link.stl" />
      </geometry>
    </collision>
  </link>
  <link name="L_F1_01">
    <inertial>
      <origin xyz="0.00039 3.121e-08 -0.014"
        rpy="-0.17662 -1.93032e-06 1.57079" />
      <mass value="0.061" />
      <inertia ixx="1.924e-05" iyy="1.70941e-05" izz="5.94788e-06"
        ixy="0" ixz="0" iyz="0" />
    </inertial>
    <visual>
      <origin xyz="0.0019 -1.00177e-06 -0.02298"
        rpy="-0.14439 1.9855e-05 1.57092" />
      <geometry>
        <mesh filename="../../../hands/tesollo_3f/meshes/visual/link_01.stl" />
      </geometry>
      <material name="black" />
    </visual>
    <collision>
      <origin xyz="0.0019 -1.00177e-06 -0.02298"
        rpy="-0.14439 1.9855e-05 1.57092" />
      <geometry>
        <mesh filename="../../../hands/tesollo_3f/meshes/visual/link_01.stl" />
      </geometry>
    </collision>
  </link>
  <link name="L_F1_02">
    <inertial>
      <origin xyz="0.01 3.444e-06 0.016"
        rpy="-0.00369 0.31689 -0.00277" />
      <mass value="0.025" />
      <inertia ixx="7.1648e-06" iyy="6.31302e-06" izz="3.27418e-06"
        ixy="0" ixz="0" iyz="0" />
    </inertial>
    <visual>
      <origin xyz="0.01032 0.00027 0.01359"
        rpy="-0.03118 0.37574 -0.02433" />
      <geometry>
        <mesh filename="../../../hands/tesollo_3f/meshes/visual/link_02.stl" />
      </geometry>
      <material name="black" />
    </visual>
    <collision>
      <origin xyz="0.01032 0.00027 0.01359"
        rpy="-0.03118 0.37574 -0.02433" />
      <geometry>
        <mesh filename="../../../hands/tesollo_3f/meshes/visual/link_02.stl" />
      </geometry>
    </collision>
  </link>
  <link name="L_F1_03">
    <inertial>
      <origin xyz="0.014 -0.00045 -3.953e-05"
        rpy="1.56511 -0.00086 1.55626" />
      <mass value="0.051" />
      <inertia ixx="1.69122e-05" iyy="1.49403e-05" izz="6.50553e-06"
        ixy="0" ixz="0" iyz="0" />
    </inertial>
    <visual>
      <origin xyz="0.01903 -0.00076 0.00016"
        rpy="1.54055 -0.00236 1.59945" />
      <geometry>
        <mesh filename="../../../hands/tesollo_3f/meshes/visual/link_03.stl" />
      </geometry>
      <material name="black" />
    </visual>
    <collision>
      <origin xyz="0.01903 -0.00076 0.00016"
        rpy="1.54055 -0.00236 1.59945" />
      <geometry>
        <mesh filename="../../../hands/tesollo_3f/meshes/visual/link_03.stl" />
      </geometry>
    </collision>
  </link>
  <link name="L_F1_04">
    <inertial>
      <origin xyz="0.012 -0.00023 -4.676e-05"
        rpy="1.56685 -0.00087 1.58297" />
      <mass value="0.058" />
      <inertia ixx="1.08608e-05" iyy="9.90207e-06" izz="5.33011e-06"
        ixy="0" ixz="0" iyz="0" />
    </inertial>
    <visual>
      <origin xyz="0.01199 -0.00077 -5.20111e-06"
        rpy="1.57453 0.0036 1.66504" />
      <geometry>
        <mesh filename="../../../hands/tesollo_3f/meshes/visual/link_04.stl" />
      </geometry>
      <material name="black" />
    </visual>
    <collision>
      <origin xyz="0.01199 -0.00077 -5.20111e-06"
        rpy="1.57453 0.0036 1.66504" />
      <geometry>
        <mesh filename="../../../hands/tesollo_3f/meshes/visual/link_04.stl" />
      </geometry>
    </collision>
  </link>
  <link name="L_F1_TIP">
    <inertial>
      <origin xyz="0.045 -0.00044 -7.22e-08"
        rpy="1.5708 -3.69536e-05 1.52109" />
      <mass value="0.013" />
      <inertia ixx="1.59657e-06" iyy="1.3e-06" izz="9.60129e-07"
        ixy="0" ixz="0" iyz="0" />
    </inertial>
    <visual>
      <origin xyz="0.04496 -0.00042 2.30189e-07"
        rpy="1.57087 -1.01999e-05 1.52041" />
      <geometry>
        <mesh filename="../../../hands/tesollo_3f/meshes/visual/link_tip_high.stl" />
      </geometry>
      <material name="white" />
    </visual>
    <collision>
      <origin xyz="0.04496 -0.00042 2.30189e-07"
        rpy="1.57087 -1.01999e-05 1.52041" />
      <geometry>
        <mesh filename="../../../hands/tesollo_3f/meshes/visual/link_tip_high.stl" />
      </geometry>
    </collision>
  </link>
  <link name="L_F2_01">
    <inertial>
      <origin xyz="0.00039 3.121e-08 -0.014"
        rpy="-0.17662 -1.93032e-06 1.57079" />
      <mass value="0.061" />
      <inertia ixx="1.924e-05" iyy="1.70941e-05" izz="5.94788e-06"
        ixy="0" ixz="0" iyz="0" />
    </inertial>
    <visual>
      <origin xyz="0.0019 -1.00177e-06 -0.02298"
        rpy="-0.14439 1.9855e-05 1.57092" />
      <geometry>
        <mesh filename="../../../hands/tesollo_3f/meshes/visual/link_01.stl" />
      </geometry>
      <material name="black" />
    </visual>
    <collision>
      <origin xyz="0.0019 -1.00177e-06 -0.02298"
        rpy="-0.14439 1.9855e-05 1.57092" />
      <geometry>
        <mesh filename="../../../hands/tesollo_3f/meshes/visual/link_01.stl" />
      </geometry>
    </collision>
  </link>
  <link name="L_F2_02">
    <inertial>
      <origin xyz="0.01 3.444e-06 0.016"
        rpy="-0.00369 0.31689 -0.00277" />
      <mass value="0.025" />
      <inertia ixx="7.1648e-06" iyy="6.31302e-06" izz="3.27418e-06"
        ixy="0" ixz="0" iyz="0" />
    </inertial>
    <visual>
      <origin xyz="0.01032 0.00027 0.01359"
        rpy="-0.03118 0.37574 -0.02433" />
      <geometry>
        <mesh filename="../../../hands/tesollo_3f/meshes/visual/link_02.stl" />
      </geometry>
      <material name="black" />
    </visual>
    <collision>
      <origin xyz="0.01032 0.00027 0.01359"
        rpy="-0.03118 0.37574 -0.02433" />
      <geometry>
        <mesh filename="../../../hands/tesollo_3f/meshes/visual/link_02.stl" />
      </geometry>
    </collision>
  </link>
  <link name="L_F2_03">
    <inertial>
      <origin xyz="0.014 -0.00045 -3.953e-05"
        rpy="1.56511 -0.00086 1.55626" />
      <mass value="0.051" />
      <inertia ixx="1.69122e-05" iyy="1.49403e-05" izz="6.50553e-06"
        ixy="0" ixz="0" iyz="0" />
    </inertial>
    <visual>
      <origin xyz="0.01903 -0.00076 0.00016"
        rpy="1.54055 -0.00236 1.59945" />
      <geometry>
        <mesh filename="../../../hands/tesollo_3f/meshes/visual/link_03.stl" />
      </geometry>
      <material name="black" />
    </visual>
    <collision>
      <origin xyz="0.01903 -0.00076 0.00016"
        rpy="1.54055 -0.00236 1.59945" />
      <geometry>
        <mesh filename="../../../hands/tesollo_3f/meshes/visual/link_03.stl" />
      </geometry>
    </collision>
  </link>
  <link name="L_F2_04">
    <inertial>
      <origin xyz="0.012 -0.00023 -4.676e-05"
        rpy="1.56685 -0.00087 1.58297" />
      <mass value="0.058" />
      <inertia ixx="1.08608e-05" iyy="9.90207e-06" izz="5.33011e-06"
        ixy="0" ixz="0" iyz="0" />
    </inertial>
    <visual>
      <origin xyz="0.01199 -0.00077 -5.20111e-06"
        rpy="1.57453 0.0036 1.66504" />
      <geometry>
        <mesh filename="../../../hands/tesollo_3f/meshes/visual/link_04.stl" />
      </geometry>
      <material name="black" />
    </visual>
    <collision>
      <origin xyz="0.01199 -0.00077 -5.20111e-06"
        rpy="1.57453 0.0036 1.66504" />
      <geometry>
        <mesh filename="../../../hands/tesollo_3f/meshes/visual/link_04.stl" />
      </geometry>
    </collision>
  </link>
  <link name="L_F2_TIP">
    <inertial>
      <origin xyz="0.045 -0.00044 -7.22e-08"
        rpy="1.5708 -3.69536e-05 1.52109" />
      <mass value="0.013" />
      <inertia ixx="1.59657e-06" iyy="1.3e-06" izz="9.60129e-07"
        ixy="0" ixz="0" iyz="0" />
    </inertial>
    <visual>
      <origin xyz="0.04496 -0.00042 2.30189e-07"
        rpy="1.57087 -1.01999e-05 1.52041" />
      <geometry>
        <mesh filename="../../../hands/tesollo_3f/meshes/visual/link_tip_high.stl" />
      </geometry>
      <material name="white" />
    </visual>
    <collision>
      <origin xyz="0.04496 -0.00042 2.30189e-07"
        rpy="1.57087 -1.01999e-05 1.52041" />
      <geometry>
        <mesh filename="../../../hands/tesollo_3f/meshes/visual/link_tip_high.stl" />
      </geometry>
    </collision>
  </link>
  <link name="L_F3_01">
    <inertial>
      <origin xyz="0.00039 3.121e-08 -0.014"
        rpy="-0.17662 -1.93032e-06 1.57079" />
      <mass value="0.061" />
      <inertia ixx="1.924e-05" iyy="1.70941e-05" izz="5.94788e-06"
        ixy="0" ixz="0" iyz="0" />
    </inertial>
    <visual>
      <origin xyz="0.0019 -1.00177e-06 -0.02298"
        rpy="-0.14439 1.9855e-05 1.57092" />
      <geometry>
        <mesh filename="../../../hands/tesollo_3f/meshes/visual/link_01.stl" />
      </geometry>
      <material name="black" />
    </visual>
    <collision>
      <origin xyz="0.0019 -1.00177e-06 -0.02298"
        rpy="-0.14439 1.9855e-05 1.57092" />
      <geometry>
        <mesh filename="../../../hands/tesollo_3f/meshes/visual/link_01.stl" />
      </geometry>
    </collision>
  </link>
  <link name="L_F3_02">
    <inertial>
      <origin xyz="0.01 3.444e-06 0.016"
        rpy="-0.00369 0.31689 -0.00277" />
      <mass value="0.025" />
      <inertia ixx="7.1648e-06" iyy="6.31302e-06" izz="3.27418e-06"
        ixy="0" ixz="0" iyz="0" />
    </inertial>
    <visual>
      <origin xyz="0.01032 0.00027 0.01359"
        rpy="-0.03118 0.37574 -0.02433" />
      <geometry>
        <mesh filename="../../../hands/tesollo_3f/meshes/visual/link_02.stl" />
      </geometry>
      <material name="black" />
    </visual>
    <collision>
      <origin xyz="0.01032 0.00027 0.01359"
        rpy="-0.03118 0.37574 -0.02433" />
      <geometry>
        <mesh filename="../../../hands/tesollo_3f/meshes/visual/link_02.stl" />
      </geometry>
    </collision>
  </link>
  <link name="L_F3_03">
    <inertial>
      <origin xyz="0.014 -0.00045 -3.953e-05"
        rpy="1.56511 -0.00086 1.55626" />
      <mass value="0.051" />
      <inertia ixx="1.69122e-05" iyy="1.49403e-05" izz="6.50553e-06"
        ixy="0" ixz="0" iyz="0" />
    </inertial>
    <visual>
      <origin xyz="0.01903 -0.00076 0.00016"
        rpy="1.54055 -0.00236 1.59945" />
      <geometry>
        <mesh filename="../../../hands/tesollo_3f/meshes/visual/link_03.stl" />
      </geometry>
      <material name="black" />
    </visual>
    <collision>
      <origin xyz="0.01903 -0.00076 0.00016"
        rpy="1.54055 -0.00236 1.59945" />
      <geometry>
        <mesh filename="../../../hands/tesollo_3f/meshes/visual/link_03.stl" />
      </geometry>
    </collision>
  </link>
  <link name="L_F3_04">
    <inertial>
      <origin xyz="0.012 -0.00023 -4.676e-05"
        rpy="1.56685 -0.00087 1.58297" />
      <mass value="0.058" />
      <inertia ixx="1.08608e-05" iyy="9.90207e-06" izz="5.33011e-06"
        ixy="0" ixz="0" iyz="0" />
    </inertial>
    <visual>
      <origin xyz="0.01199 -0.00077 -5.20111e-06"
        rpy="1.57453 0.0036 1.66504" />
      <geometry>
        <mesh filename="../../../hands/tesollo_3f/meshes/visual/link_04.stl" />
      </geometry>
      <material name="black" />
    </visual>
    <collision>
      <origin xyz="0.01199 -0.00077 -5.20111e-06"
        rpy="1.57453 0.0036 1.66504" />
      <geometry>
        <mesh filename="../../../hands/tesollo_3f/meshes/visual/link_04.stl" />
      </geometry>
    </collision>
  </link>
  <link name="L_F3_TIP">
    <inertial>
      <origin xyz="0.045 -0.00044 -7.22e-08"
        rpy="1.5708 -3.69536e-05 1.52109" />
      <mass value="0.013" />
      <inertia ixx="1.59657e-06" iyy="1.3e-06" izz="9.60129e-07"
        ixy="0" ixz="0" iyz="0" />
    </inertial>
    <visual>
      <origin xyz="0.04496 -0.00042 2.30189e-07"
        rpy="1.57087 -1.01999e-05 1.52041" />
      <geometry>
        <mesh filename="../../../hands/tesollo_3f/meshes/visual/link_tip_high.stl" />
      </geometry>
      <material name="white" />
    </visual>
    <collision>
      <origin xyz="0.04496 -0.00042 2.30189e-07"
        rpy="1.57087 -1.01999e-05 1.52041" />
      <geometry>
        <mesh filename="../../../hands/tesollo_3f/meshes/visual/link_tip_high.stl" />
      </geometry>
    </collision>
  </link>

  <!--Joint -->
  <joint name="L_F1M1" type="revolute">
    <origin xyz="0.0265 0.0 0.0" rpy="0 0 0" />
    <parent link="L_hand_base" />
    <child link="L_F1_01" />
    <axis xyz="0.0 0.0 1.0" />
    <limit effort="10.0" velocity="5.0" lower="-1.0472" upper="1.0472" />
    <dynamics damping="1.1" friction="1.1" />
  </joint>
  <joint name="L_F1M2" type="revolute">
    <origin xyz="0.0 0.0 0.0" rpy="-3.14159 -1.5708 0.0" />
    <parent link="L_F1_01" />
    <child link="L_F1_02" />
    <axis xyz="0.0 0.0 1.0" />
    <limit effort="10.0" velocity="5.0" lower="-1.76278" upper="1.76278" />
    <dynamics damping="1.1" friction="1.1" />
  </joint>
  <joint name="L_F1M3" type="revolute">
    <origin xyz="0.02022 0.0 0.03136" rpy="-1.5708 -1.5708 0.0" />
    <parent link="L_F1_02" />
    <child link="L_F1_03" />
    <axis xyz="0.0 0.0 1.0" />
    <limit effort="10.0" velocity="5.0" lower="-0.15708" upper="2.53073" />
    <dynamics damping="1.1" friction="1.1" />
  </joint>
  <joint name="L_F1M4" type="revolute">
    <origin xyz="0.0434 0.0 0.0" rpy="0 0 0" />
    <parent link="L_F1_03" />
    <child link="L_F1_04" />
    <axis xyz="0.0 0.0 1.0" />
    <limit effort="10.0" velocity="5.0" lower="-0.22689" upper="2.02458" />
    <dynamics damping="1.1" friction="1.1" />
  </joint>
  <joint name="L_TIP1" type="fixed">
    <origin xyz="0.0 0.0 0.0" rpy="0 0 0" />
    <parent link="L_F1_04" />
    <child link="L_F1_TIP" />
  </joint>

  <!-- FINGER 2-->
  <joint name="L_F2M1" type="revolute">
    <origin xyz="-0.01334 0.023 0.0" rpy="0 0 -3.14" />
    <parent link="L_hand_base" />
    <child link="L_F2_01" />
    <axis xyz="0.0 0.0 1.0" />
    <limit effort="10.0" velocity="5.0" lower="-1.91986" upper="0.13963" />
    <dynamics damping="1.1" friction="1.1" />
  </joint>
  <joint name="L_F2M2" type="revolute">
    <origin xyz="0.0 0.0 0.0" rpy="-3.14 -1.57 0" />
    <parent link="L_F2_01" />
    <child link="L_F2_02" />
    <axis xyz="0.0 0.0 1.0" />
    <limit effort="10.0" velocity="5.0" lower="-1.76278" upper="1.76278" />
    <dynamics damping="1.1" friction="1.1" />
  </joint>
  <joint name="L_F2M3" type="revolute">
    <origin xyz="0.02022 0.0 0.03136" rpy="-1.57 -1.57 0" />
    <parent link="L_F2_02" />
    <child link="L_F2_03" />
    <axis xyz="0.0 0.0 1.0" />
    <limit effort="10.0" velocity="5.0" lower="-0.15708" upper="2.53073" />
    <dynamics damping="1.1" friction="1.1" />
  </joint>
  <joint name="L_F2M4" type="revolute">
    <origin xyz="0.0434 0.0 0.0" rpy="0 0 0" />
    <parent link="L_F2_03" />
    <child link="L_F2_04" />
    <axis xyz="0.0434 0.0 1.0" />
    <limit effort="10.0" velocity="5.0" lower="-0.22689" upper="2.02458" />
    <dynamics damping="1.1" friction="1.1" />
  </joint>
  <joint name="L_TIP2" type="fixed">
    <origin xyz="0.0 0.0 0.0" rpy="0 0 0" />
    <parent link="L_F2_04" />
    <child link="L_F2_TIP" />
  </joint>

  <!-- FINGER 3-->
  <joint name="L_F3M1" type="revolute">
    <origin xyz="-0.01334 -0.023 0.0" rpy="0 0 -3.14" />
    <parent link="L_hand_base" />
    <child link="L_F3_01" />
    <axis xyz=".0 0.0 1.0" />
    <limit effort="10.0" velocity="5.0" lower="-0.08727" upper="2.00713" />
    <dynamics damping="1.1" friction="1.1" />
  </joint>
  <joint name="L_F3M2" type="revolute">
    <origin xyz="0.0 0.0 0.0" rpy="-3.14 -1.57 0" />
    <parent link="L_F3_01" />
    <child link="L_F3_02" />
    <axis xyz="0.0 0.0 1.0" />
    <limit effort="10.0" velocity="5.0" lower="-1.76278" upper="1.76278" />
    <dynamics damping="1.1" friction="1.1" />
  </joint>
  <joint name="L_F3M3" type="revolute">
    <origin xyz="0.02022 0.0 0.03136" rpy="-1.57 -1.57 0" />
    <parent link="L_F3_02" />
    <child link="L_F3_03" />
    <axis xyz="0.0 0.0 1.0" />
    <limit effort="10.0" velocity="5.0" lower="-0.15708" upper="2.53073" />
    <dynamics damping="1.1" friction="1.1" />
  </joint>
  <joint name="L_F3M4" type="revolute">
    <origin xyz="0.0434 0.0 0.0" rpy="0 0 0" />
    <parent link="L_F3_03" />
    <child link="L_F3_04" />
    <axis xyz="0.0 0.0 1.0" />
    <limit effort="10.0" velocity="5.0" lower="-0.22689" upper="2.02458" />
    <dynamics damping="1.1" friction="1.1" />
  </joint>
  <joint name="L_TIP3" type="fixed">
    <origin xyz="0.0 0.0 0.0" rpy="0 0 0" />
    <parent link="L_F3_04" />
    <child link="L_F3_TIP" />
  </joint>

  <!-- Right Hand with Tesollo 3F Gripper -->
  <joint name="R_hand_mount" type="fixed">
    <origin xyz="0.10727 0 0" rpy="-1.5708 0 -1.5708" />
    <parent link="R_arm_l8" />
    <child link="R_hand_base" />
  </joint>
  <link name="R_hand_base">
    <inertial>
      <origin xyz="0.00045 -2.05165e-06 -0.05219"
        rpy="5.67132e-06 0.00329 -0.00045" />
      <mass value="0.370" />
      <inertia ixx="0.00099" iyy="0.00098" izz="0.00032"
        ixy="0" ixz="0" iyz="0" />
    </inertial>
    <visual>
      <origin xyz="0 0 -0.11077" rpy="0 -1.5708 0" />
      <geometry>
        <mesh filename="../../../hands/tesollo_3f/meshes/visual/adapter.stl" />
      </geometry>
      <material name="black" />
    </visual>
    <visual>
      <origin xyz="0.00045 -2.05165e-06 -0.05219"
        rpy="5.67132e-06 0.00329 -0.00045" />
      <geometry>
        <mesh filename="../../../hands/tesollo_3f/meshes/visual/delto_base_link.stl" />
      </geometry>
      <material name="black" />
    </visual>
    <collision>
      <origin xyz="0.00045 -2.05165e-06 -0.05219"
        rpy="5.67132e-06 0.00329 -0.00045" />
      <geometry>
        <mesh filename="../../../hands/tesollo_3f/meshes/visual/delto_base_link.stl" />
      </geometry>
    </collision>
  </link>
  <link name="R_F1_01">
    <inertial>
      <origin xyz="0.00039 3.121e-08 -0.014"
        rpy="-0.17662 -1.93032e-06 1.57079" />
      <mass value="0.061" />
      <inertia ixx="1.924e-05" iyy="1.70941e-05" izz="5.94788e-06"
        ixy="0" ixz="0" iyz="0" />
    </inertial>
    <visual>
      <origin xyz="0.0019 -1.00177e-06 -0.02298"
        rpy="-0.14439 1.9855e-05 1.57092" />
      <geometry>
        <mesh filename="../../../hands/tesollo_3f/meshes/visual/link_01.stl" />
      </geometry>
      <material name="black" />
    </visual>
    <collision>
      <origin xyz="0.0019 -1.00177e-06 -0.02298"
        rpy="-0.14439 1.9855e-05 1.57092" />
      <geometry>
        <mesh filename="../../../hands/tesollo_3f/meshes/visual/link_01.stl" />
      </geometry>
    </collision>
  </link>
  <link name="R_F1_02">
    <inertial>
      <origin xyz="0.01 3.444e-06 0.016"
        rpy="-0.00369 0.31689 -0.00277" />
      <mass value="0.025" />
      <inertia ixx="7.1648e-06" iyy="6.31302e-06" izz="3.27418e-06"
        ixy="0" ixz="0" iyz="0" />
    </inertial>
    <visual>
      <origin xyz="0.01032 0.00027 0.01359"
        rpy="-0.03118 0.37574 -0.02433" />
      <geometry>
        <mesh filename="../../../hands/tesollo_3f/meshes/visual/link_02.stl" />
      </geometry>
      <material name="black" />
    </visual>
    <collision>
      <origin xyz="0.01032 0.00027 0.01359"
        rpy="-0.03118 0.37574 -0.02433" />
      <geometry>
        <mesh filename="../../../hands/tesollo_3f/meshes/visual/link_02.stl" />
      </geometry>
    </collision>
  </link>
  <link name="R_F1_03">
    <inertial>
      <origin xyz="0.014 -0.00045 -3.953e-05"
        rpy="1.56511 -0.00086 1.55626" />
      <mass value="0.051" />
      <inertia ixx="1.69122e-05" iyy="1.49403e-05" izz="6.50553e-06"
        ixy="0" ixz="0" iyz="0" />
    </inertial>
    <visual>
      <origin xyz="0.01903 -0.00076 0.00016"
        rpy="1.54055 -0.00236 1.59945" />
      <geometry>
        <mesh filename="../../../hands/tesollo_3f/meshes/visual/link_03.stl" />
      </geometry>
      <material name="black" />
    </visual>
    <collision>
      <origin xyz="0.01903 -0.00076 0.00016"
        rpy="1.54055 -0.00236 1.59945" />
      <geometry>
        <mesh filename="../../../hands/tesollo_3f/meshes/visual/link_03.stl" />
      </geometry>
    </collision>
  </link>
  <link name="R_F1_04">
    <inertial>
      <origin xyz="0.012 -0.00023 -4.676e-05"
        rpy="1.56685 -0.00087 1.58297" />
      <mass value="0.058" />
      <inertia ixx="1.08608e-05" iyy="9.90207e-06" izz="5.33011e-06"
        ixy="0" ixz="0" iyz="0" />
    </inertial>
    <visual>
      <origin xyz="0.01199 -0.00077 -5.20111e-06"
        rpy="1.57453 0.0036 1.66504" />
      <geometry>
        <mesh filename="../../../hands/tesollo_3f/meshes/visual/link_04.stl" />
      </geometry>
      <material name="black" />
    </visual>
    <collision>
      <origin xyz="0.01199 -0.00077 -5.20111e-06"
        rpy="1.57453 0.0036 1.66504" />
      <geometry>
        <mesh filename="../../../hands/tesollo_3f/meshes/visual/link_04.stl" />
      </geometry>
    </collision>
  </link>
  <link name="R_F1_TIP">
    <inertial>
      <origin xyz="0.045 -0.00044 -7.22e-08"
        rpy="1.5708 -3.69536e-05 1.52109" />
      <mass value="0.013" />
      <inertia ixx="1.59657e-06" iyy="1.3e-06" izz="9.60129e-07"
        ixy="0" ixz="0" iyz="0" />
    </inertial>
    <visual>
      <origin xyz="0.04496 -0.00042 2.30189e-07"
        rpy="1.57087 -1.01999e-05 1.52041" />
      <geometry>
        <mesh filename="../../../hands/tesollo_3f/meshes/visual/link_tip_high.stl" />
      </geometry>
      <material name="white" />
    </visual>
    <collision>
      <origin xyz="0.04496 -0.00042 2.30189e-07"
        rpy="1.57087 -1.01999e-05 1.52041" />
      <geometry>
        <mesh filename="../../../hands/tesollo_3f/meshes/visual/link_tip_high.stl" />
      </geometry>
    </collision>
  </link>
  <link name="R_F2_01">
    <inertial>
      <origin xyz="0.00039 3.121e-08 -0.014"
        rpy="-0.17662 -1.93032e-06 1.57079" />
      <mass value="0.061" />
      <inertia ixx="1.924e-05" iyy="1.70941e-05" izz="5.94788e-06"
        ixy="0" ixz="0" iyz="0" />
    </inertial>
    <visual>
      <origin xyz="0.0019 -1.00177e-06 -0.02298"
        rpy="-0.14439 1.9855e-05 1.57092" />
      <geometry>
        <mesh filename="../../../hands/tesollo_3f/meshes/visual/link_01.stl" />
      </geometry>
      <material name="black" />
    </visual>
    <collision>
      <origin xyz="0.0019 -1.00177e-06 -0.02298"
        rpy="-0.14439 1.9855e-05 1.57092" />
      <geometry>
        <mesh filename="../../../hands/tesollo_3f/meshes/visual/link_01.stl" />
      </geometry>
    </collision>
  </link>
  <link name="R_F2_02">
    <inertial>
      <origin xyz="0.01 3.444e-06 0.016"
        rpy="-0.00369 0.31689 -0.00277" />
      <mass value="0.025" />
      <inertia ixx="7.1648e-06" iyy="6.31302e-06" izz="3.27418e-06"
        ixy="0" ixz="0" iyz="0" />
    </inertial>
    <visual>
      <origin xyz="0.01032 0.00027 0.01359"
        rpy="-0.03118 0.37574 -0.02433" />
      <geometry>
        <mesh filename="../../../hands/tesollo_3f/meshes/visual/link_02.stl" />
      </geometry>
      <material name="black" />
    </visual>
    <collision>
      <origin xyz="0.01032 0.00027 0.01359"
        rpy="-0.03118 0.37574 -0.02433" />
      <geometry>
        <mesh filename="../../../hands/tesollo_3f/meshes/visual/link_02.stl" />
      </geometry>
    </collision>
  </link>

  <link name="R_F2_03">
    <inertial>
      <origin xyz="0.014 -0.00045 -3.953e-05"
        rpy="1.56511 -0.00086 1.55626" />
      <mass value="0.051" />
      <inertia ixx="1.69122e-05" iyy="1.49403e-05" izz="6.50553e-06"
        ixy="0" ixz="0" iyz="0" />
    </inertial>
    <visual>
      <origin xyz="0.01903 -0.00076 0.00016"
        rpy="1.54055 -0.00236 1.59945" />
      <geometry>
        <mesh filename="../../../hands/tesollo_3f/meshes/visual/link_03.stl" />
      </geometry>
      <material name="black" />
    </visual>
    <collision>
      <origin xyz="0.01903 -0.00076 0.00016"
        rpy="1.54055 -0.00236 1.59945" />
      <geometry>
        <mesh filename="../../../hands/tesollo_3f/meshes/visual/link_03.stl" />
      </geometry>
    </collision>
  </link>
  <link name="R_F2_04">
    <inertial>
      <origin xyz="0.012 -0.00023 -4.676e-05"
        rpy="1.56685 -0.00087 1.58297" />
      <mass value="0.058" />
      <inertia ixx="1.08608e-05" iyy="9.90207e-06" izz="5.33011e-06"
        ixy="0" ixz="0" iyz="0" />
    </inertial>
    <visual>
      <origin xyz="0.01199 -0.00077 -5.20111e-06"
        rpy="1.57453 0.0036 1.66504" />
      <geometry>
        <mesh filename="../../../hands/tesollo_3f/meshes/visual/link_04.stl" />
      </geometry>
      <material name="black" />
    </visual>
    <collision>
      <origin xyz="0.01199 -0.00077 -5.20111e-06"
        rpy="1.57453 0.0036 1.66504" />
      <geometry>
        <mesh filename="../../../hands/tesollo_3f/meshes/visual/link_04.stl" />
      </geometry>
    </collision>
  </link>
  <link name="R_F2_TIP">
    <inertial>
      <origin xyz="0.045 -0.00044 -7.22e-08"
        rpy="1.5708 -3.69536e-05 1.52109" />
      <mass value="0.013" />
      <inertia ixx="1.59657e-06" iyy="1.3e-06" izz="9.60129e-07"
        ixy="0" ixz="0" iyz="0" />
    </inertial>
    <visual>
      <origin xyz="0.04496 -0.00042 2.30189e-07"
        rpy="1.57087 -1.01999e-05 1.52041" />
      <geometry>
        <mesh filename="../../../hands/tesollo_3f/meshes/visual/link_tip_high.stl" />
      </geometry>
      <material name="white" />
    </visual>
    <collision>
      <origin xyz="0.04496 -0.00042 2.30189e-07"
        rpy="1.57087 -1.01999e-05 1.52041" />
      <geometry>
        <mesh filename="../../../hands/tesollo_3f/meshes/visual/link_tip_high.stl" />
      </geometry>
    </collision>
  </link>
  <link name="R_F3_01">
    <inertial>
      <origin xyz="0.00039 3.121e-08 -0.014"
        rpy="-0.17662 -1.93032e-06 1.57079" />
      <mass value="0.061" />
      <inertia ixx="1.924e-05" iyy="1.70941e-05" izz="5.94788e-06"
        ixy="0" ixz="0" iyz="0" />
    </inertial>
    <visual>
      <origin xyz="0.0019 -1.00177e-06 -0.02298"
        rpy="-0.14439 1.9855e-05 1.57092" />
      <geometry>
        <mesh filename="../../../hands/tesollo_3f/meshes/visual/link_01.stl" />
      </geometry>
      <material name="black" />
    </visual>
    <collision>
      <origin xyz="0.0019 -1.00177e-06 -0.02298"
        rpy="-0.14439 1.9855e-05 1.57092" />
      <geometry>
        <mesh filename="../../../hands/tesollo_3f/meshes/visual/link_01.stl" />
      </geometry>
    </collision>
  </link>
  <link name="R_F3_02">
    <inertial>
      <origin xyz="0.01 3.444e-06 0.016"
        rpy="-0.00369 0.31689 -0.00277" />
      <mass value="0.025" />
      <inertia ixx="7.1648e-06" iyy="6.31302e-06" izz="3.27418e-06"
        ixy="0" ixz="0" iyz="0" />
    </inertial>
    <visual>
      <origin xyz="0.01032 0.00027 0.01359"
        rpy="-0.03118 0.37574 -0.02433" />
      <geometry>
        <mesh filename="../../../hands/tesollo_3f/meshes/visual/link_02.stl" />
      </geometry>
      <material name="black" />
    </visual>
    <collision>
      <origin xyz="0.01032 0.00027 0.01359"
        rpy="-0.03118 0.37574 -0.02433" />
      <geometry>
        <mesh filename="../../../hands/tesollo_3f/meshes/visual/link_02.stl" />
      </geometry>
    </collision>
  </link>
  <link name="R_F3_03">
    <inertial>
      <origin xyz="0.014 -0.00045 -3.953e-05"
        rpy="1.56511 -0.00086 1.55626" />
      <mass value="0.051" />
      <inertia ixx="1.69122e-05" iyy="1.49403e-05" izz="6.50553e-06"
        ixy="0" ixz="0" iyz="0" />
    </inertial>
    <visual>
      <origin xyz="0.01903 -0.00076 0.00016"
        rpy="1.54055 -0.00236 1.59945" />
      <geometry>
        <mesh filename="../../../hands/tesollo_3f/meshes/visual/link_03.stl" />
      </geometry>
      <material name="black" />
    </visual>
    <collision>
      <origin xyz="0.01903 -0.00076 0.00016"
        rpy="1.54055 -0.00236 1.59945" />
      <geometry>
        <mesh filename="../../../hands/tesollo_3f/meshes/visual/link_03.stl" />
      </geometry>
    </collision>
  </link>
  <link name="R_F3_04">
    <inertial>
      <origin xyz="0.012 -0.00023 -4.676e-05"
        rpy="1.56685 -0.00087 1.58297" />
      <mass value="0.058" />
      <inertia ixx="1.08608e-05" iyy="9.90207e-06" izz="5.33011e-06"
        ixy="0" ixz="0" iyz="0" />
    </inertial>
    <visual>
      <origin xyz="0.01199 -0.00077 -5.20111e-06"
        rpy="1.57453 0.0036 1.66504" />
      <geometry>
        <mesh filename="../../../hands/tesollo_3f/meshes/visual/link_04.stl" />
      </geometry>
      <material name="black" />
    </visual>
    <collision>
      <origin xyz="0.01199 -0.00077 -5.20111e-06"
        rpy="1.57453 0.0036 1.66504" />
      <geometry>
        <mesh filename="../../../hands/tesollo_3f/meshes/visual/link_04.stl" />
      </geometry>
    </collision>
  </link>
  <link name="R_F3_TIP">
    <inertial>
      <origin xyz="0.045 -0.00044 -7.22e-08"
        rpy="1.5708 -3.69536e-05 1.52109" />
      <mass value="0.013" />
      <inertia ixx="1.59657e-06" iyy="1.3e-06" izz="9.60129e-07"
        ixy="0" ixz="0" iyz="0" />
    </inertial>
    <visual>
      <origin xyz="0.04496 -0.00042 2.30189e-07"
        rpy="1.57087 -1.01999e-05 1.52041" />
      <geometry>
        <mesh filename="../../../hands/tesollo_3f/meshes/visual/link_tip_high.stl" />
      </geometry>
      <material name="white" />
    </visual>
    <collision>
      <origin xyz="0.04496 -0.00042 2.30189e-07"
        rpy="1.57087 -1.01999e-05 1.52041" />
      <geometry>
        <mesh filename="../../../hands/tesollo_3f/meshes/visual/link_tip_high.stl" />
      </geometry>
    </collision>
  </link>

  <!--Joint -->
  <joint name="R_F1M1" type="revolute">
    <origin xyz="0.0265 0.0 0.0" rpy="0 0 0" />
    <parent link="R_hand_base" />
    <child link="R_F1_01" />
    <axis xyz="0.0 0.0 1.0" />
    <limit effort="10.0" velocity="5.0" lower="-1.0472" upper="1.0472" />
    <dynamics damping="1.1" friction="1.1" />
  </joint>
  <joint name="R_F1M2" type="revolute">
    <origin xyz="0.0 0.0 0.0" rpy="-3.14159 -1.5708 0.0" />
    <parent link="R_F1_01" />
    <child link="R_F1_02" />
    <axis xyz="0.0 0.0 1.0" />
    <limit effort="10.0" velocity="5.0" lower="-1.76278" upper="1.76278" />
    <dynamics damping="1.1" friction="1.1" />
  </joint>
  <joint name="R_F1M3" type="revolute">
    <origin xyz="0.02022 0.0 0.03136" rpy="-1.5708 -1.5708 0.0" />
    <parent link="R_F1_02" />
    <child link="R_F1_03" />
    <axis xyz="0.0 0.0 1.0" />
    <limit effort="10.0" velocity="5.0" lower="-0.15708" upper="2.53073" />
    <dynamics damping="1.1" friction="1.1" />
  </joint>
  <joint name="R_F1M4" type="revolute">
    <origin xyz="0.0434 0.0 0.0" rpy="0 0 0" />
    <parent link="R_F1_03" />
    <child link="R_F1_04" />
    <axis xyz="0.0 0.0 1.0" />
    <limit effort="10.0" velocity="5.0" lower="-0.22689" upper="2.02458" />
    <dynamics damping="1.1" friction="1.1" />
  </joint>
  <joint name="R_TIP1" type="fixed">
    <origin xyz="0.0 0.0 0.0" rpy="0 0 0" />
    <parent link="R_F1_04" />
    <child link="R_F1_TIP" />
  </joint>

  <!-- FINGER 2-->
  <joint name="R_F2M1" type="revolute">
    <origin xyz="-0.01334 0.023 0.0" rpy="0 0 -3.14" />
    <parent link="R_hand_base" />
    <child link="R_F2_01" />
    <axis xyz="0.0 0.0 1.0" />
    <limit effort="10.0" velocity="5.0" lower="-1.91986" upper="0.13963" />
    <dynamics damping="1.1" friction="1.1" />
  </joint>
  <joint name="R_F2M2" type="revolute">
    <origin xyz="0.0 0.0 0.0" rpy="-3.14 -1.57 0" />
    <parent link="R_F2_01" />
    <child link="R_F2_02" />
    <axis xyz="0.0 0.0 1.0" />
    <limit effort="10.0" velocity="5.0" lower="-1.76278" upper="1.76278" />
    <dynamics damping="1.1" friction="1.1" />
  </joint>
  <joint name="R_F2M3" type="revolute">
    <origin xyz="0.02022 0.0 0.03136" rpy="-1.57 -1.57 0" />
    <parent link="R_F2_02" />
    <child link="R_F2_03" />
    <axis xyz="0.0 0.0 1.0" />
    <limit effort="10.0" velocity="5.0" lower="-0.15708" upper="2.53073" />
    <dynamics damping="1.1" friction="1.1" />
  </joint>
  <joint name="R_F2M4" type="revolute">
    <origin xyz="0.0434 0.0 0.0" rpy="0 0 0" />
    <parent link="R_F2_03" />
    <child link="R_F2_04" />
    <axis xyz="0.0434 0.0 1.0" />
    <limit effort="10.0" velocity="5.0" lower="-0.22689" upper="2.02458" />
    <dynamics damping="1.1" friction="1.1" />
  </joint>
  <joint name="R_TIP2" type="fixed">
    <origin xyz="0.0 0.0 0.0" rpy="0 0 0" />
    <parent link="R_F2_04" />
    <child link="R_F2_TIP" />
  </joint>

  <!-- FINGER 3-->
  <joint name="R_F3M1" type="revolute">
    <origin xyz="-0.01334 -0.023 0.0" rpy="0 0 -3.14" />
    <parent link="R_hand_base" />
    <child link="R_F3_01" />
    <axis xyz=".0 0.0 1.0" />
    <limit effort="10.0" velocity="5.0" lower="-0.08727" upper="2.00713" />
    <dynamics damping="1.1" friction="1.1" />
  </joint>
  <joint name="R_F3M2" type="revolute">
    <origin xyz="0.0 0.0 0.0" rpy="-3.14 -1.57 0" />
    <parent link="R_F3_01" />
    <child link="R_F3_02" />
    <axis xyz="0.0 0.0 1.0" />
    <limit effort="10.0" velocity="5.0" lower="-1.76278" upper="1.76278" />
    <dynamics damping="1.1" friction="1.1" />
  </joint>
  <joint name="R_F3M3" type="revolute">
    <origin xyz="0.02022 0.0 0.03136" rpy="-1.57 -1.57 0" />
    <parent link="R_F3_02" />
    <child link="R_F3_03" />
    <axis xyz="0.0 0.0 1.0" />
    <limit effort="10.0" velocity="5.0" lower="-0.15708" upper="2.53073" />
    <dynamics damping="1.1" friction="1.1" />
  </joint>
  <joint name="R_F3M4" type="revolute">
    <origin xyz="0.0434 0.0 0.0" rpy="0 0 0" />
    <parent link="R_F3_03" />
    <child link="R_F3_04" />
    <axis xyz="0.0 0.0 1.0" />
    <limit effort="10.0" velocity="5.0" lower="-0.22689" upper="2.02458" />
    <dynamics damping="1.1" friction="1.1" />
  </joint>
  <joint name="R_TIP3" type="fixed">
    <origin xyz="0.0 0.0 0.0" rpy="0 0 0" />
    <parent link="R_F3_04" />
    <child link="R_F3_TIP" />
  </joint>
</robot>